// Finally Ã© executada independente do resultado do try/catch

// Pode existir com try e catch ou apenas try

try{
    let c = a + b;
} catch(error){
    console.log('Algo deu errado:' + error)
} finally {
    console.log("Executou");
}


